Exception in thread Thread-1:
Traceback (most recent call last):
  File "/usr/lib/python3.8/threading.py", line 932, in _bootstrap_inner
    self.run()
  File "/home/it62070007/frappe-bench/env/lib/python3.8/site-packages/redis/client.py", line 3718, in run
    pubsub.get_message(ignore_subscribe_messages=True,
  File "/home/it62070007/frappe-bench/env/lib/python3.8/site-packages/redis/client.py", line 3617, in get_message
    response = self.parse_response(block=False, timeout=timeout)
  File "/home/it62070007/frappe-bench/env/lib/python3.8/site-packages/redis/client.py", line 3503, in parse_response
    if not block and not conn.can_read(timeout=timeout):
  File "/home/it62070007/frappe-bench/env/lib/python3.8/site-packages/redis/connection.py", line 734, in can_read
    return self._parser.can_read(timeout)
  File "/home/it62070007/frappe-bench/env/lib/python3.8/site-packages/redis/connection.py", line 321, in can_read
    return self._buffer and self._buffer.can_read(timeout)
  File "/home/it62070007/frappe-bench/env/lib/python3.8/site-packages/redis/connection.py", line 230, in can_read
    self._read_from_socket(timeout=timeout,
  File "/home/it62070007/frappe-bench/env/lib/python3.8/site-packages/redis/connection.py", line 201, in _read_from_socket
    raise ConnectionError(SERVER_CLOSED_CONNECTION_ERROR)
redis.exceptions.ConnectionError: Connection closed by server.
Exception in thread Thread-1:
Traceback (most recent call last):
  File "/usr/lib/python3.8/threading.py", line 932, in _bootstrap_inner
Exception in thread Thread-1:
Traceback (most recent call last):
  File "/usr/lib/python3.8/threading.py", line 932, in _bootstrap_inner
Exception in thread Thread-1:
Traceback (most recent call last):
  File "/usr/lib/python3.8/threading.py", line 932, in _bootstrap_inner
--- Logging error ---
--- Logging error ---
--- Logging error ---
    self.run()
  File "/home/it62070007/frappe-bench/env/lib/python3.8/site-packages/redis/client.py", line 3718, in run
    self.run()
  File "/home/it62070007/frappe-bench/env/lib/python3.8/site-packages/redis/client.py", line 3718, in run
    self.run()
  File "/home/it62070007/frappe-bench/env/lib/python3.8/site-packages/redis/client.py", line 3718, in run
    pubsub.get_message(ignore_subscribe_messages=True,
  File "/home/it62070007/frappe-bench/env/lib/python3.8/site-packages/redis/client.py", line 3617, in get_message
    response = self.parse_response(block=False, timeout=timeout)
  File "/home/it62070007/frappe-bench/env/lib/python3.8/site-packages/redis/client.py", line 3503, in parse_response
    if not block and not conn.can_read(timeout=timeout):
  File "/home/it62070007/frappe-bench/env/lib/python3.8/site-packages/redis/connection.py", line 734, in can_read
    pubsub.get_message(ignore_subscribe_messages=True,
  File "/home/it62070007/frappe-bench/env/lib/python3.8/site-packages/redis/client.py", line 3617, in get_message
    response = self.parse_response(block=False, timeout=timeout)
  File "/home/it62070007/frappe-bench/env/lib/python3.8/site-packages/redis/client.py", line 3503, in parse_response
    if not block and not conn.can_read(timeout=timeout):
  File "/home/it62070007/frappe-bench/env/lib/python3.8/site-packages/redis/connection.py", line 734, in can_read
    pubsub.get_message(ignore_subscribe_messages=True,
  File "/home/it62070007/frappe-bench/env/lib/python3.8/site-packages/redis/client.py", line 3617, in get_message
    response = self.parse_response(block=False, timeout=timeout)
  File "/home/it62070007/frappe-bench/env/lib/python3.8/site-packages/redis/client.py", line 3503, in parse_response
    if not block and not conn.can_read(timeout=timeout):
  File "/home/it62070007/frappe-bench/env/lib/python3.8/site-packages/redis/connection.py", line 734, in can_read
    return self._parser.can_read(timeout)
  File "/home/it62070007/frappe-bench/env/lib/python3.8/site-packages/redis/connection.py", line 321, in can_read
    return self._parser.can_read(timeout)
  File "/home/it62070007/frappe-bench/env/lib/python3.8/site-packages/redis/connection.py", line 321, in can_read
    return self._buffer and self._buffer.can_read(timeout)
  File "/home/it62070007/frappe-bench/env/lib/python3.8/site-packages/redis/connection.py", line 230, in can_read
    self._read_from_socket(timeout=timeout,
  File "/home/it62070007/frappe-bench/env/lib/python3.8/site-packages/redis/connection.py", line 201, in _read_from_socket
    raise ConnectionError(SERVER_CLOSED_CONNECTION_ERROR)
redis.exceptions.ConnectionError: Connection closed by server.
    return self._parser.can_read(timeout)
  File "/home/it62070007/frappe-bench/env/lib/python3.8/site-packages/redis/connection.py", line 321, in can_read
    return self._buffer and self._buffer.can_read(timeout)
  File "/home/it62070007/frappe-bench/env/lib/python3.8/site-packages/redis/connection.py", line 230, in can_read
    self._read_from_socket(timeout=timeout,
  File "/home/it62070007/frappe-bench/env/lib/python3.8/site-packages/redis/connection.py", line 201, in _read_from_socket
    raise ConnectionError(SERVER_CLOSED_CONNECTION_ERROR)
redis.exceptions.ConnectionError: Connection closed by server.
    return self._buffer and self._buffer.can_read(timeout)
  File "/home/it62070007/frappe-bench/env/lib/python3.8/site-packages/redis/connection.py", line 230, in can_read
    self._read_from_socket(timeout=timeout,
  File "/home/it62070007/frappe-bench/env/lib/python3.8/site-packages/redis/connection.py", line 201, in _read_from_socket
    raise ConnectionError(SERVER_CLOSED_CONNECTION_ERROR)
redis.exceptions.ConnectionError: Connection closed by server.
Traceback (most recent call last):
  File "/home/it62070007/frappe-bench/env/lib/python3.8/site-packages/rq/worker.py", line 572, in work
    result = self.dequeue_job_and_maintain_ttl(timeout)
  File "/home/it62070007/frappe-bench/env/lib/python3.8/site-packages/rq/worker.py", line 639, in dequeue_job_and_maintain_ttl
    result = self.queue_class.dequeue_any(self.queues, timeout,
  File "/home/it62070007/frappe-bench/env/lib/python3.8/site-packages/rq/queue.py", line 600, in dequeue_any
    result = cls.lpop(queue_keys, timeout, connection=connection)
  File "/home/it62070007/frappe-bench/env/lib/python3.8/site-packages/rq/queue.py", line 572, in lpop
    result = connection.blpop(queue_keys, timeout)
  File "/home/it62070007/frappe-bench/env/lib/python3.8/site-packages/redis/client.py", line 1900, in blpop
    return self.execute_command('BLPOP', *keys)
  File "/home/it62070007/frappe-bench/env/lib/python3.8/site-packages/redis/client.py", line 901, in execute_command
    return self.parse_response(conn, command_name, **options)
  File "/home/it62070007/frappe-bench/env/lib/python3.8/site-packages/redis/client.py", line 915, in parse_response
    response = connection.read_response()
  File "/home/it62070007/frappe-bench/env/lib/python3.8/site-packages/redis/connection.py", line 739, in read_response
    response = self._parser.read_response()
  File "/home/it62070007/frappe-bench/env/lib/python3.8/site-packages/redis/connection.py", line 324, in read_response
    raw = self._buffer.readline()
  File "/home/it62070007/frappe-bench/env/lib/python3.8/site-packages/redis/connection.py", line 256, in readline
    self._read_from_socket()
  File "/home/it62070007/frappe-bench/env/lib/python3.8/site-packages/redis/connection.py", line 201, in _read_from_socket
    raise ConnectionError(SERVER_CLOSED_CONNECTION_ERROR)
redis.exceptions.ConnectionError: Connection closed by server.

During handling of the above exception, another exception occurred:

Traceback (most recent call last):
  File "/usr/lib/python3.8/logging/__init__.py", line 1081, in emit
    msg = self.format(record)
  File "/home/it62070007/frappe-bench/env/lib/python3.8/site-packages/rq/utils.py", line 113, in format
    message = logging.StreamHandler.format(self, record)
  File "/usr/lib/python3.8/logging/__init__.py", line 925, in format
    return fmt.format(record)
  File "/usr/lib/python3.8/logging/__init__.py", line 672, in format
    record.exc_text = self.formatException(record.exc_info)
  File "/usr/lib/python3.8/logging/__init__.py", line 622, in formatException
    traceback.print_exception(ei[0], ei[1], tb, None, sio)
  File "/usr/lib/python3.8/traceback.py", line 103, in print_exception
    for line in TracebackException(
  File "/usr/lib/python3.8/traceback.py", line 509, in __init__
    self.stack = StackSummary.extract(
  File "/usr/lib/python3.8/traceback.py", line 366, in extract
    f.line
  File "/usr/lib/python3.8/traceback.py", line 288, in line
    self._line = linecache.getline(self.filename, self.lineno).strip()
  File "/home/it62070007/frappe-bench/env/lib/python3.8/linecache.py", line 16, in getline
    lines = getlines(filename, module_globals)
  File "/home/it62070007/frappe-bench/env/lib/python3.8/linecache.py", line 47, in getlines
    return updatecache(filename, module_globals)
  File "/home/it62070007/frappe-bench/env/lib/python3.8/linecache.py", line 137, in updatecache
    lines = fp.readlines()
  File "/home/it62070007/frappe-bench/env/lib/python3.8/codecs.py", line 319, in decode
    def decode(self, input, final=False):
  File "/home/it62070007/frappe-bench/env/lib/python3.8/site-packages/rq/worker.py", line 448, in request_stop
    self._shutdown()
  File "/home/it62070007/frappe-bench/env/lib/python3.8/site-packages/rq/worker.py", line 465, in _shutdown
    raise StopRequested()
rq.worker.StopRequested
Call stack:
Traceback (most recent call last):
  File "/home/it62070007/frappe-bench/env/lib/python3.8/site-packages/rq/worker.py", line 572, in work
    result = self.dequeue_job_and_maintain_ttl(timeout)
  File "/home/it62070007/frappe-bench/env/lib/python3.8/site-packages/rq/worker.py", line 639, in dequeue_job_and_maintain_ttl
    result = self.queue_class.dequeue_any(self.queues, timeout,
  File "/home/it62070007/frappe-bench/env/lib/python3.8/site-packages/rq/queue.py", line 600, in dequeue_any
    result = cls.lpop(queue_keys, timeout, connection=connection)
  File "/home/it62070007/frappe-bench/env/lib/python3.8/site-packages/rq/queue.py", line 572, in lpop
    result = connection.blpop(queue_keys, timeout)
  File "/home/it62070007/frappe-bench/env/lib/python3.8/site-packages/redis/client.py", line 1900, in blpop
    return self.execute_command('BLPOP', *keys)
  File "/home/it62070007/frappe-bench/env/lib/python3.8/site-packages/redis/client.py", line 901, in execute_command
    return self.parse_response(conn, command_name, **options)
  File "/home/it62070007/frappe-bench/env/lib/python3.8/site-packages/redis/client.py", line 915, in parse_response
    response = connection.read_response()
  File "/home/it62070007/frappe-bench/env/lib/python3.8/site-packages/redis/connection.py", line 739, in read_response
    response = self._parser.read_response()
  File "/home/it62070007/frappe-bench/env/lib/python3.8/site-packages/redis/connection.py", line 324, in read_response
    raw = self._buffer.readline()
  File "/home/it62070007/frappe-bench/env/lib/python3.8/site-packages/redis/connection.py", line 256, in readline
    self._read_from_socket()
  File "/home/it62070007/frappe-bench/env/lib/python3.8/site-packages/redis/connection.py", line 201, in _read_from_socket
    raise ConnectionError(SERVER_CLOSED_CONNECTION_ERROR)
redis.exceptions.ConnectionError: Connection closed by server.

During handling of the above exception, another exception occurred:

Traceback (most recent call last):
  File "/usr/lib/python3.8/logging/__init__.py", line 1081, in emit
    msg = self.format(record)
  File "/home/it62070007/frappe-bench/env/lib/python3.8/site-packages/rq/utils.py", line 113, in format
    message = logging.StreamHandler.format(self, record)
  File "/usr/lib/python3.8/logging/__init__.py", line 925, in format
    return fmt.format(record)
  File "/usr/lib/python3.8/logging/__init__.py", line 672, in format
    record.exc_text = self.formatException(record.exc_info)
  File "/usr/lib/python3.8/logging/__init__.py", line 622, in formatException
    traceback.print_exception(ei[0], ei[1], tb, None, sio)
  File "/usr/lib/python3.8/traceback.py", line 103, in print_exception
    for line in TracebackException(
  File "/usr/lib/python3.8/traceback.py", line 509, in __init__
    self.stack = StackSummary.extract(
  File "/usr/lib/python3.8/traceback.py", line 366, in extract
    f.line
  File "/usr/lib/python3.8/traceback.py", line 288, in line
    self._line = linecache.getline(self.filename, self.lineno).strip()
  File "/home/it62070007/frappe-bench/env/lib/python3.8/linecache.py", line 16, in getline
    lines = getlines(filename, module_globals)
  File "/home/it62070007/frappe-bench/env/lib/python3.8/linecache.py", line 47, in getlines
    return updatecache(filename, module_globals)
  File "/home/it62070007/frappe-bench/env/lib/python3.8/linecache.py", line 137, in updatecache
    lines = fp.readlines()
  File "/home/it62070007/frappe-bench/env/lib/python3.8/codecs.py", line 319, in decode
    def decode(self, input, final=False):
  File "/home/it62070007/frappe-bench/env/lib/python3.8/site-packages/rq/worker.py", line 448, in request_stop
    self._shutdown()
  File "/home/it62070007/frappe-bench/env/lib/python3.8/site-packages/rq/worker.py", line 465, in _shutdown
    raise StopRequested()
rq.worker.StopRequested
Call stack:
Traceback (most recent call last):
  File "/home/it62070007/frappe-bench/env/lib/python3.8/site-packages/rq/worker.py", line 572, in work
    result = self.dequeue_job_and_maintain_ttl(timeout)
  File "/home/it62070007/frappe-bench/env/lib/python3.8/site-packages/rq/worker.py", line 639, in dequeue_job_and_maintain_ttl
    result = self.queue_class.dequeue_any(self.queues, timeout,
  File "/home/it62070007/frappe-bench/env/lib/python3.8/site-packages/rq/queue.py", line 600, in dequeue_any
    result = cls.lpop(queue_keys, timeout, connection=connection)
  File "/home/it62070007/frappe-bench/env/lib/python3.8/site-packages/rq/queue.py", line 572, in lpop
    result = connection.blpop(queue_keys, timeout)
  File "/home/it62070007/frappe-bench/env/lib/python3.8/site-packages/redis/client.py", line 1900, in blpop
    return self.execute_command('BLPOP', *keys)
  File "/home/it62070007/frappe-bench/env/lib/python3.8/site-packages/redis/client.py", line 901, in execute_command
    return self.parse_response(conn, command_name, **options)
  File "/home/it62070007/frappe-bench/env/lib/python3.8/site-packages/redis/client.py", line 915, in parse_response
    response = connection.read_response()
  File "/home/it62070007/frappe-bench/env/lib/python3.8/site-packages/redis/connection.py", line 739, in read_response
    response = self._parser.read_response()
  File "/home/it62070007/frappe-bench/env/lib/python3.8/site-packages/redis/connection.py", line 324, in read_response
    raw = self._buffer.readline()
  File "/home/it62070007/frappe-bench/env/lib/python3.8/site-packages/redis/connection.py", line 256, in readline
    self._read_from_socket()
  File "/home/it62070007/frappe-bench/env/lib/python3.8/site-packages/redis/connection.py", line 201, in _read_from_socket
    raise ConnectionError(SERVER_CLOSED_CONNECTION_ERROR)
redis.exceptions.ConnectionError: Connection closed by server.

During handling of the above exception, another exception occurred:

Traceback (most recent call last):
  File "/usr/lib/python3.8/logging/__init__.py", line 1081, in emit
    msg = self.format(record)
  File "/home/it62070007/frappe-bench/env/lib/python3.8/site-packages/rq/utils.py", line 113, in format
    message = logging.StreamHandler.format(self, record)
  File "/usr/lib/python3.8/logging/__init__.py", line 925, in format
    return fmt.format(record)
  File "/usr/lib/python3.8/logging/__init__.py", line 672, in format
    record.exc_text = self.formatException(record.exc_info)
  File "/usr/lib/python3.8/logging/__init__.py", line 622, in formatException
    traceback.print_exception(ei[0], ei[1], tb, None, sio)
  File "/usr/lib/python3.8/traceback.py", line 103, in print_exception
    for line in TracebackException(
  File "/usr/lib/python3.8/traceback.py", line 509, in __init__
    self.stack = StackSummary.extract(
  File "/usr/lib/python3.8/traceback.py", line 366, in extract
    f.line
  File "/usr/lib/python3.8/traceback.py", line 288, in line
    self._line = linecache.getline(self.filename, self.lineno).strip()
  File "/home/it62070007/frappe-bench/env/lib/python3.8/linecache.py", line 16, in getline
    lines = getlines(filename, module_globals)
  File "/home/it62070007/frappe-bench/env/lib/python3.8/linecache.py", line 47, in getlines
    return updatecache(filename, module_globals)
  File "/home/it62070007/frappe-bench/env/lib/python3.8/linecache.py", line 137, in updatecache
    lines = fp.readlines()
  File "/home/it62070007/frappe-bench/env/lib/python3.8/codecs.py", line 319, in decode
    def decode(self, input, final=False):
  File "/home/it62070007/frappe-bench/env/lib/python3.8/site-packages/rq/worker.py", line 448, in request_stop
    self._shutdown()
  File "/home/it62070007/frappe-bench/env/lib/python3.8/site-packages/rq/worker.py", line 465, in _shutdown
    raise StopRequested()
rq.worker.StopRequested
Call stack:
  File "/usr/lib/python3.8/runpy.py", line 194, in _run_module_as_main
    return _run_code(code, main_globals, None,
  File "/usr/lib/python3.8/runpy.py", line 87, in _run_code
    exec(code, run_globals)
  File "/home/it62070007/frappe-bench/apps/frappe/frappe/utils/bench_helper.py", line 99, in <module>
    main()
  File "/home/it62070007/frappe-bench/apps/frappe/frappe/utils/bench_helper.py", line 18, in main
    click.Group(commands=commands)(prog_name='bench')
  File "/home/it62070007/frappe-bench/env/lib/python3.8/site-packages/click/core.py", line 764, in __call__
    return self.main(*args, **kwargs)
  File "/home/it62070007/frappe-bench/env/lib/python3.8/site-packages/click/core.py", line 717, in main
    rv = self.invoke(ctx)
  File "/home/it62070007/frappe-bench/env/lib/python3.8/site-packages/click/core.py", line 1137, in invoke
    return _process_result(sub_ctx.command.invoke(sub_ctx))
  File "/home/it62070007/frappe-bench/env/lib/python3.8/site-packages/click/core.py", line 1137, in invoke
    return _process_result(sub_ctx.command.invoke(sub_ctx))
  File "/home/it62070007/frappe-bench/env/lib/python3.8/site-packages/click/core.py", line 956, in invoke
    return ctx.invoke(self.callback, **ctx.params)
  File "/home/it62070007/frappe-bench/env/lib/python3.8/site-packages/click/core.py", line 555, in invoke
    return callback(*args, **kwargs)
  File "/home/it62070007/frappe-bench/apps/frappe/frappe/commands/scheduler.py", line 167, in start_worker
    start_worker(queue, quiet = quiet)
  File "/home/it62070007/frappe-bench/apps/frappe/frappe/utils/background_jobs.py", line 151, in start_worker
    Worker(queues, name=get_worker_name(queue)).work(logging_level = logging_level)
  File "/home/it62070007/frappe-bench/env/lib/python3.8/site-packages/rq/worker.py", line 599, in work
    self.log.error(
Message: 'Worker %s: found an unhandled exception, quitting...'
Arguments: ('rq:worker:6b96811ca7644a439ad9ee31828a5dec.it62070007-VirtualBox.1941.long',)
Traceback (most recent call last):
  File "/home/it62070007/frappe-bench/env/lib/python3.8/site-packages/redis/connection.py", line 559, in connect
    sock = self._connect()
  File "/home/it62070007/frappe-bench/env/lib/python3.8/site-packages/redis/connection.py", line 615, in _connect
    raise err
  File "/home/it62070007/frappe-bench/env/lib/python3.8/site-packages/redis/connection.py", line 603, in _connect
    sock.connect(socket_address)
ConnectionRefusedError: [Errno 111] Connection refused

During handling of the above exception, another exception occurred:

Traceback (most recent call last):
  File "/usr/lib/python3.8/runpy.py", line 194, in _run_module_as_main
    return _run_code(code, main_globals, None,
  File "/usr/lib/python3.8/runpy.py", line 87, in _run_code
    exec(code, run_globals)
  File "/home/it62070007/frappe-bench/apps/frappe/frappe/utils/bench_helper.py", line 99, in <module>
    main()
  File "/home/it62070007/frappe-bench/apps/frappe/frappe/utils/bench_helper.py", line 18, in main
    click.Group(commands=commands)(prog_name='bench')
  File "/home/it62070007/frappe-bench/env/lib/python3.8/site-packages/click/core.py", line 764, in __call__
    return self.main(*args, **kwargs)
  File "/home/it62070007/frappe-bench/env/lib/python3.8/site-packages/click/core.py", line 717, in main
    rv = self.invoke(ctx)
  File "/home/it62070007/frappe-bench/env/lib/python3.8/site-packages/click/core.py", line 1137, in invoke
    return _process_result(sub_ctx.command.invoke(sub_ctx))
  File "/home/it62070007/frappe-bench/env/lib/python3.8/site-packages/click/core.py", line 1137, in invoke
    return _process_result(sub_ctx.command.invoke(sub_ctx))
  File "/home/it62070007/frappe-bench/env/lib/python3.8/site-packages/click/core.py", line 956, in invoke
    return ctx.invoke(self.callback, **ctx.params)
  File "/home/it62070007/frappe-bench/env/lib/python3.8/site-packages/click/core.py", line 555, in invoke
    return callback(*args, **kwargs)
  File "/home/it62070007/frappe-bench/apps/frappe/frappe/commands/scheduler.py", line 167, in start_worker
    start_worker(queue, quiet = quiet)
  File "/home/it62070007/frappe-bench/apps/frappe/frappe/utils/background_jobs.py", line 151, in start_worker
    Worker(queues, name=get_worker_name(queue)).work(logging_level = logging_level)
  File "/home/it62070007/frappe-bench/env/lib/python3.8/site-packages/rq/worker.py", line 610, in work
    self.register_death()
  File "/home/it62070007/frappe-bench/env/lib/python3.8/site-packages/rq/worker.py", line 318, in register_death
    p.execute()
  File "/home/it62070007/frappe-bench/env/lib/python3.8/site-packages/redis/client.py", line 4012, in execute
    conn = self.connection_pool.get_connection('MULTI',
  File "/home/it62070007/frappe-bench/env/lib/python3.8/site-packages/redis/connection.py", line 1192, in get_connection
    connection.connect()
  File "/home/it62070007/frappe-bench/env/lib/python3.8/site-packages/redis/connection.py", line 563, in connect
    raise ConnectionError(self._error_message(e))
redis.exceptions.ConnectionError: Error 111 connecting to localhost:11000. Connection refused.
  File "/usr/lib/python3.8/runpy.py", line 194, in _run_module_as_main
    return _run_code(code, main_globals, None,
  File "/usr/lib/python3.8/runpy.py", line 87, in _run_code
    exec(code, run_globals)
  File "/home/it62070007/frappe-bench/apps/frappe/frappe/utils/bench_helper.py", line 99, in <module>
    main()
  File "/home/it62070007/frappe-bench/apps/frappe/frappe/utils/bench_helper.py", line 18, in main
    click.Group(commands=commands)(prog_name='bench')
  File "/home/it62070007/frappe-bench/env/lib/python3.8/site-packages/click/core.py", line 764, in __call__
    return self.main(*args, **kwargs)
  File "/home/it62070007/frappe-bench/env/lib/python3.8/site-packages/click/core.py", line 717, in main
    rv = self.invoke(ctx)
  File "/home/it62070007/frappe-bench/env/lib/python3.8/site-packages/click/core.py", line 1137, in invoke
    return _process_result(sub_ctx.command.invoke(sub_ctx))
  File "/home/it62070007/frappe-bench/env/lib/python3.8/site-packages/click/core.py", line 1137, in invoke
    return _process_result(sub_ctx.command.invoke(sub_ctx))
  File "/home/it62070007/frappe-bench/env/lib/python3.8/site-packages/click/core.py", line 956, in invoke
    return ctx.invoke(self.callback, **ctx.params)
  File "/home/it62070007/frappe-bench/env/lib/python3.8/site-packages/click/core.py", line 555, in invoke
    return callback(*args, **kwargs)
  File "/home/it62070007/frappe-bench/apps/frappe/frappe/commands/scheduler.py", line 167, in start_worker
    start_worker(queue, quiet = quiet)
  File "/home/it62070007/frappe-bench/apps/frappe/frappe/utils/background_jobs.py", line 151, in start_worker
    Worker(queues, name=get_worker_name(queue)).work(logging_level = logging_level)
  File "/home/it62070007/frappe-bench/env/lib/python3.8/site-packages/rq/worker.py", line 599, in work
    self.log.error(
Message: 'Worker %s: found an unhandled exception, quitting...'
Arguments: ('rq:worker:beb431767b3b41c8b9ab6c18168a82cf.it62070007-VirtualBox.1952.default',)
Traceback (most recent call last):
  File "/home/it62070007/frappe-bench/env/lib/python3.8/site-packages/redis/connection.py", line 559, in connect
    sock = self._connect()
  File "/home/it62070007/frappe-bench/env/lib/python3.8/site-packages/redis/connection.py", line 615, in _connect
    raise err
  File "/home/it62070007/frappe-bench/env/lib/python3.8/site-packages/redis/connection.py", line 603, in _connect
    sock.connect(socket_address)
ConnectionRefusedError: [Errno 111] Connection refused

During handling of the above exception, another exception occurred:

Traceback (most recent call last):
  File "/usr/lib/python3.8/runpy.py", line 194, in _run_module_as_main
    return _run_code(code, main_globals, None,
  File "/usr/lib/python3.8/runpy.py", line 87, in _run_code
    exec(code, run_globals)
  File "/home/it62070007/frappe-bench/apps/frappe/frappe/utils/bench_helper.py", line 99, in <module>
    main()
  File "/home/it62070007/frappe-bench/apps/frappe/frappe/utils/bench_helper.py", line 18, in main
    click.Group(commands=commands)(prog_name='bench')
  File "/home/it62070007/frappe-bench/env/lib/python3.8/site-packages/click/core.py", line 764, in __call__
    return self.main(*args, **kwargs)
  File "/home/it62070007/frappe-bench/env/lib/python3.8/site-packages/click/core.py", line 717, in main
    rv = self.invoke(ctx)
  File "/home/it62070007/frappe-bench/env/lib/python3.8/site-packages/click/core.py", line 1137, in invoke
    return _process_result(sub_ctx.command.invoke(sub_ctx))
  File "/home/it62070007/frappe-bench/env/lib/python3.8/site-packages/click/core.py", line 1137, in invoke
    return _process_result(sub_ctx.command.invoke(sub_ctx))
  File "/home/it62070007/frappe-bench/env/lib/python3.8/site-packages/click/core.py", line 956, in invoke
    return ctx.invoke(self.callback, **ctx.params)
  File "/home/it62070007/frappe-bench/env/lib/python3.8/site-packages/click/core.py", line 555, in invoke
    return callback(*args, **kwargs)
  File "/home/it62070007/frappe-bench/apps/frappe/frappe/commands/scheduler.py", line 167, in start_worker
    start_worker(queue, quiet = quiet)
  File "/home/it62070007/frappe-bench/apps/frappe/frappe/utils/background_jobs.py", line 151, in start_worker
    Worker(queues, name=get_worker_name(queue)).work(logging_level = logging_level)
  File "/home/it62070007/frappe-bench/env/lib/python3.8/site-packages/rq/worker.py", line 610, in work
    self.register_death()
  File "/home/it62070007/frappe-bench/env/lib/python3.8/site-packages/rq/worker.py", line 318, in register_death
    p.execute()
  File "/home/it62070007/frappe-bench/env/lib/python3.8/site-packages/redis/client.py", line 4012, in execute
    conn = self.connection_pool.get_connection('MULTI',
  File "/home/it62070007/frappe-bench/env/lib/python3.8/site-packages/redis/connection.py", line 1192, in get_connection
    connection.connect()
  File "/home/it62070007/frappe-bench/env/lib/python3.8/site-packages/redis/connection.py", line 563, in connect
    raise ConnectionError(self._error_message(e))
redis.exceptions.ConnectionError: Error 111 connecting to localhost:11000. Connection refused.
  File "/usr/lib/python3.8/runpy.py", line 194, in _run_module_as_main
    return _run_code(code, main_globals, None,
  File "/usr/lib/python3.8/runpy.py", line 87, in _run_code
    exec(code, run_globals)
  File "/home/it62070007/frappe-bench/apps/frappe/frappe/utils/bench_helper.py", line 99, in <module>
    main()
  File "/home/it62070007/frappe-bench/apps/frappe/frappe/utils/bench_helper.py", line 18, in main
    click.Group(commands=commands)(prog_name='bench')
  File "/home/it62070007/frappe-bench/env/lib/python3.8/site-packages/click/core.py", line 764, in __call__
    return self.main(*args, **kwargs)
  File "/home/it62070007/frappe-bench/env/lib/python3.8/site-packages/click/core.py", line 717, in main
    rv = self.invoke(ctx)
  File "/home/it62070007/frappe-bench/env/lib/python3.8/site-packages/click/core.py", line 1137, in invoke
    return _process_result(sub_ctx.command.invoke(sub_ctx))
  File "/home/it62070007/frappe-bench/env/lib/python3.8/site-packages/click/core.py", line 1137, in invoke
    return _process_result(sub_ctx.command.invoke(sub_ctx))
  File "/home/it62070007/frappe-bench/env/lib/python3.8/site-packages/click/core.py", line 956, in invoke
    return ctx.invoke(self.callback, **ctx.params)
  File "/home/it62070007/frappe-bench/env/lib/python3.8/site-packages/click/core.py", line 555, in invoke
    return callback(*args, **kwargs)
  File "/home/it62070007/frappe-bench/apps/frappe/frappe/commands/scheduler.py", line 167, in start_worker
    start_worker(queue, quiet = quiet)
  File "/home/it62070007/frappe-bench/apps/frappe/frappe/utils/background_jobs.py", line 151, in start_worker
    Worker(queues, name=get_worker_name(queue)).work(logging_level = logging_level)
  File "/home/it62070007/frappe-bench/env/lib/python3.8/site-packages/rq/worker.py", line 599, in work
    self.log.error(
Message: 'Worker %s: found an unhandled exception, quitting...'
Arguments: ('rq:worker:0e93e522ba57422a8ecf77999a78bcd1.it62070007-VirtualBox.1947.short',)
Traceback (most recent call last):
  File "/home/it62070007/frappe-bench/env/lib/python3.8/site-packages/redis/connection.py", line 559, in connect
    sock = self._connect()
  File "/home/it62070007/frappe-bench/env/lib/python3.8/site-packages/redis/connection.py", line 615, in _connect
    raise err
  File "/home/it62070007/frappe-bench/env/lib/python3.8/site-packages/redis/connection.py", line 603, in _connect
    sock.connect(socket_address)
ConnectionRefusedError: [Errno 111] Connection refused

During handling of the above exception, another exception occurred:

Traceback (most recent call last):
  File "/usr/lib/python3.8/runpy.py", line 194, in _run_module_as_main
    return _run_code(code, main_globals, None,
  File "/usr/lib/python3.8/runpy.py", line 87, in _run_code
    exec(code, run_globals)
  File "/home/it62070007/frappe-bench/apps/frappe/frappe/utils/bench_helper.py", line 99, in <module>
    main()
  File "/home/it62070007/frappe-bench/apps/frappe/frappe/utils/bench_helper.py", line 18, in main
    click.Group(commands=commands)(prog_name='bench')
  File "/home/it62070007/frappe-bench/env/lib/python3.8/site-packages/click/core.py", line 764, in __call__
    return self.main(*args, **kwargs)
  File "/home/it62070007/frappe-bench/env/lib/python3.8/site-packages/click/core.py", line 717, in main
    rv = self.invoke(ctx)
  File "/home/it62070007/frappe-bench/env/lib/python3.8/site-packages/click/core.py", line 1137, in invoke
    return _process_result(sub_ctx.command.invoke(sub_ctx))
  File "/home/it62070007/frappe-bench/env/lib/python3.8/site-packages/click/core.py", line 1137, in invoke
    return _process_result(sub_ctx.command.invoke(sub_ctx))
  File "/home/it62070007/frappe-bench/env/lib/python3.8/site-packages/click/core.py", line 956, in invoke
    return ctx.invoke(self.callback, **ctx.params)
  File "/home/it62070007/frappe-bench/env/lib/python3.8/site-packages/click/core.py", line 555, in invoke
    return callback(*args, **kwargs)
  File "/home/it62070007/frappe-bench/apps/frappe/frappe/commands/scheduler.py", line 167, in start_worker
    start_worker(queue, quiet = quiet)
  File "/home/it62070007/frappe-bench/apps/frappe/frappe/utils/background_jobs.py", line 151, in start_worker
    Worker(queues, name=get_worker_name(queue)).work(logging_level = logging_level)
  File "/home/it62070007/frappe-bench/env/lib/python3.8/site-packages/rq/worker.py", line 610, in work
    self.register_death()
  File "/home/it62070007/frappe-bench/env/lib/python3.8/site-packages/rq/worker.py", line 318, in register_death
    p.execute()
  File "/home/it62070007/frappe-bench/env/lib/python3.8/site-packages/redis/client.py", line 4012, in execute
    conn = self.connection_pool.get_connection('MULTI',
  File "/home/it62070007/frappe-bench/env/lib/python3.8/site-packages/redis/connection.py", line 1192, in get_connection
    connection.connect()
  File "/home/it62070007/frappe-bench/env/lib/python3.8/site-packages/redis/connection.py", line 563, in connect
    raise ConnectionError(self._error_message(e))
redis.exceptions.ConnectionError: Error 111 connecting to localhost:11000. Connection refused.
Traceback (most recent call last):
  File "/home/it62070007/frappe-bench/env/lib/python3.8/site-packages/redis/connection.py", line 559, in connect
Traceback (most recent call last):
  File "/home/it62070007/frappe-bench/env/lib/python3.8/site-packages/redis/connection.py", line 559, in connect
Traceback (most recent call last):
  File "/home/it62070007/frappe-bench/env/lib/python3.8/site-packages/redis/connection.py", line 559, in connect
    sock = self._connect()
  File "/home/it62070007/frappe-bench/env/lib/python3.8/site-packages/redis/connection.py", line 615, in _connect
    raise err
  File "/home/it62070007/frappe-bench/env/lib/python3.8/site-packages/redis/connection.py", line 603, in _connect
    sock.connect(socket_address)
ConnectionRefusedError: [Errno 111] Connection refused

During handling of the above exception, another exception occurred:

Traceback (most recent call last):
  File "/usr/lib/python3.8/runpy.py", line 194, in _run_module_as_main
    sock = self._connect()
  File "/home/it62070007/frappe-bench/env/lib/python3.8/site-packages/redis/connection.py", line 615, in _connect
    raise err
  File "/home/it62070007/frappe-bench/env/lib/python3.8/site-packages/redis/connection.py", line 603, in _connect
    sock.connect(socket_address)
ConnectionRefusedError: [Errno 111] Connection refused

During handling of the above exception, another exception occurred:

Traceback (most recent call last):
  File "/usr/lib/python3.8/runpy.py", line 194, in _run_module_as_main
    sock = self._connect()
  File "/home/it62070007/frappe-bench/env/lib/python3.8/site-packages/redis/connection.py", line 615, in _connect
    raise err
  File "/home/it62070007/frappe-bench/env/lib/python3.8/site-packages/redis/connection.py", line 603, in _connect
    sock.connect(socket_address)
ConnectionRefusedError: [Errno 111] Connection refused

During handling of the above exception, another exception occurred:

Traceback (most recent call last):
  File "/usr/lib/python3.8/runpy.py", line 194, in _run_module_as_main
    return _run_code(code, main_globals, None,
  File "/usr/lib/python3.8/runpy.py", line 87, in _run_code
    exec(code, run_globals)
  File "/home/it62070007/frappe-bench/apps/frappe/frappe/utils/bench_helper.py", line 99, in <module>
    return _run_code(code, main_globals, None,
  File "/usr/lib/python3.8/runpy.py", line 87, in _run_code
    exec(code, run_globals)
  File "/home/it62070007/frappe-bench/apps/frappe/frappe/utils/bench_helper.py", line 99, in <module>
    return _run_code(code, main_globals, None,
  File "/usr/lib/python3.8/runpy.py", line 87, in _run_code
    exec(code, run_globals)
  File "/home/it62070007/frappe-bench/apps/frappe/frappe/utils/bench_helper.py", line 99, in <module>
    main()
  File "/home/it62070007/frappe-bench/apps/frappe/frappe/utils/bench_helper.py", line 18, in main
    click.Group(commands=commands)(prog_name='bench')
  File "/home/it62070007/frappe-bench/env/lib/python3.8/site-packages/click/core.py", line 764, in __call__
    main()
  File "/home/it62070007/frappe-bench/apps/frappe/frappe/utils/bench_helper.py", line 18, in main
    click.Group(commands=commands)(prog_name='bench')
  File "/home/it62070007/frappe-bench/env/lib/python3.8/site-packages/click/core.py", line 764, in __call__
    main()
  File "/home/it62070007/frappe-bench/apps/frappe/frappe/utils/bench_helper.py", line 18, in main
    click.Group(commands=commands)(prog_name='bench')
  File "/home/it62070007/frappe-bench/env/lib/python3.8/site-packages/click/core.py", line 764, in __call__
    return self.main(*args, **kwargs)
  File "/home/it62070007/frappe-bench/env/lib/python3.8/site-packages/click/core.py", line 717, in main
    rv = self.invoke(ctx)
  File "/home/it62070007/frappe-bench/env/lib/python3.8/site-packages/click/core.py", line 1137, in invoke
    return _process_result(sub_ctx.command.invoke(sub_ctx))
  File "/home/it62070007/frappe-bench/env/lib/python3.8/site-packages/click/core.py", line 1137, in invoke
    return _process_result(sub_ctx.command.invoke(sub_ctx))
  File "/home/it62070007/frappe-bench/env/lib/python3.8/site-packages/click/core.py", line 956, in invoke
    return ctx.invoke(self.callback, **ctx.params)
  File "/home/it62070007/frappe-bench/env/lib/python3.8/site-packages/click/core.py", line 555, in invoke
    return callback(*args, **kwargs)
  File "/home/it62070007/frappe-bench/apps/frappe/frappe/commands/scheduler.py", line 167, in start_worker
    return self.main(*args, **kwargs)
  File "/home/it62070007/frappe-bench/env/lib/python3.8/site-packages/click/core.py", line 717, in main
    rv = self.invoke(ctx)
  File "/home/it62070007/frappe-bench/env/lib/python3.8/site-packages/click/core.py", line 1137, in invoke
    return _process_result(sub_ctx.command.invoke(sub_ctx))
  File "/home/it62070007/frappe-bench/env/lib/python3.8/site-packages/click/core.py", line 1137, in invoke
    return _process_result(sub_ctx.command.invoke(sub_ctx))
  File "/home/it62070007/frappe-bench/env/lib/python3.8/site-packages/click/core.py", line 956, in invoke
    return ctx.invoke(self.callback, **ctx.params)
  File "/home/it62070007/frappe-bench/env/lib/python3.8/site-packages/click/core.py", line 555, in invoke
    return callback(*args, **kwargs)
  File "/home/it62070007/frappe-bench/apps/frappe/frappe/commands/scheduler.py", line 167, in start_worker
    return self.main(*args, **kwargs)
  File "/home/it62070007/frappe-bench/env/lib/python3.8/site-packages/click/core.py", line 717, in main
    rv = self.invoke(ctx)
  File "/home/it62070007/frappe-bench/env/lib/python3.8/site-packages/click/core.py", line 1137, in invoke
    return _process_result(sub_ctx.command.invoke(sub_ctx))
  File "/home/it62070007/frappe-bench/env/lib/python3.8/site-packages/click/core.py", line 1137, in invoke
    return _process_result(sub_ctx.command.invoke(sub_ctx))
  File "/home/it62070007/frappe-bench/env/lib/python3.8/site-packages/click/core.py", line 956, in invoke
    return ctx.invoke(self.callback, **ctx.params)
  File "/home/it62070007/frappe-bench/env/lib/python3.8/site-packages/click/core.py", line 555, in invoke
    return callback(*args, **kwargs)
  File "/home/it62070007/frappe-bench/apps/frappe/frappe/commands/scheduler.py", line 167, in start_worker
    start_worker(queue, quiet = quiet)
  File "/home/it62070007/frappe-bench/apps/frappe/frappe/utils/background_jobs.py", line 151, in start_worker
    start_worker(queue, quiet = quiet)
  File "/home/it62070007/frappe-bench/apps/frappe/frappe/utils/background_jobs.py", line 151, in start_worker
    start_worker(queue, quiet = quiet)
  File "/home/it62070007/frappe-bench/apps/frappe/frappe/utils/background_jobs.py", line 151, in start_worker
    Worker(queues, name=get_worker_name(queue)).work(logging_level = logging_level)
  File "/home/it62070007/frappe-bench/env/lib/python3.8/site-packages/rq/worker.py", line 611, in work
    Worker(queues, name=get_worker_name(queue)).work(logging_level = logging_level)
  File "/home/it62070007/frappe-bench/env/lib/python3.8/site-packages/rq/worker.py", line 611, in work
    Worker(queues, name=get_worker_name(queue)).work(logging_level = logging_level)
  File "/home/it62070007/frappe-bench/env/lib/python3.8/site-packages/rq/worker.py", line 611, in work
    self.unsubscribe()
  File "/home/it62070007/frappe-bench/env/lib/python3.8/site-packages/rq/worker.py", line 520, in unsubscribe
    self.pubsub.unsubscribe()
  File "/home/it62070007/frappe-bench/env/lib/python3.8/site-packages/redis/client.py", line 3600, in unsubscribe
    self.unsubscribe()
  File "/home/it62070007/frappe-bench/env/lib/python3.8/site-packages/rq/worker.py", line 520, in unsubscribe
    self.pubsub.unsubscribe()
  File "/home/it62070007/frappe-bench/env/lib/python3.8/site-packages/redis/client.py", line 3600, in unsubscribe
    self.unsubscribe()
  File "/home/it62070007/frappe-bench/env/lib/python3.8/site-packages/rq/worker.py", line 520, in unsubscribe
    self.pubsub.unsubscribe()
  File "/home/it62070007/frappe-bench/env/lib/python3.8/site-packages/redis/client.py", line 3600, in unsubscribe
    return self.execute_command('UNSUBSCRIBE', *args)
  File "/home/it62070007/frappe-bench/env/lib/python3.8/site-packages/redis/client.py", line 3466, in execute_command
    return self.execute_command('UNSUBSCRIBE', *args)
  File "/home/it62070007/frappe-bench/env/lib/python3.8/site-packages/redis/client.py", line 3466, in execute_command
    self.connection = self.connection_pool.get_connection(
  File "/home/it62070007/frappe-bench/env/lib/python3.8/site-packages/redis/connection.py", line 1192, in get_connection
    connection.connect()
  File "/home/it62070007/frappe-bench/env/lib/python3.8/site-packages/redis/connection.py", line 563, in connect
    raise ConnectionError(self._error_message(e))
redis.exceptions.ConnectionError: Error 111 connecting to localhost:11000. Connection refused.
    return self.execute_command('UNSUBSCRIBE', *args)
  File "/home/it62070007/frappe-bench/env/lib/python3.8/site-packages/redis/client.py", line 3466, in execute_command
    self.connection = self.connection_pool.get_connection(
  File "/home/it62070007/frappe-bench/env/lib/python3.8/site-packages/redis/connection.py", line 1192, in get_connection
    connection.connect()
  File "/home/it62070007/frappe-bench/env/lib/python3.8/site-packages/redis/connection.py", line 563, in connect
    raise ConnectionError(self._error_message(e))
redis.exceptions.ConnectionError: Error 111 connecting to localhost:11000. Connection refused.
    self.connection = self.connection_pool.get_connection(
  File "/home/it62070007/frappe-bench/env/lib/python3.8/site-packages/redis/connection.py", line 1192, in get_connection
    connection.connect()
  File "/home/it62070007/frappe-bench/env/lib/python3.8/site-packages/redis/connection.py", line 563, in connect
    raise ConnectionError(self._error_message(e))
redis.exceptions.ConnectionError: Error 111 connecting to localhost:11000. Connection refused.
Traceback (most recent call last):
  File "/home/it62070007/frappe-bench/env/lib/python3.8/site-packages/redis/connection.py", line 198, in _read_from_socket
    data = recv(self._sock, socket_read_size)
  File "/home/it62070007/frappe-bench/env/lib/python3.8/site-packages/redis/_compat.py", line 72, in recv
    return sock.recv(*args, **kwargs)
ConnectionResetError: [Errno 104] Connection reset by peer

During handling of the above exception, another exception occurred:

Traceback (most recent call last):
  File "/usr/lib/python3.8/runpy.py", line 194, in _run_module_as_main
    return _run_code(code, main_globals, None,
  File "/usr/lib/python3.8/runpy.py", line 87, in _run_code
    exec(code, run_globals)
  File "/home/it62070007/frappe-bench/apps/frappe/frappe/utils/bench_helper.py", line 99, in <module>
    main()
  File "/home/it62070007/frappe-bench/apps/frappe/frappe/utils/bench_helper.py", line 18, in main
    click.Group(commands=commands)(prog_name='bench')
  File "/home/it62070007/frappe-bench/env/lib/python3.8/site-packages/click/core.py", line 764, in __call__
    return self.main(*args, **kwargs)
  File "/home/it62070007/frappe-bench/env/lib/python3.8/site-packages/click/core.py", line 717, in main
    rv = self.invoke(ctx)
  File "/home/it62070007/frappe-bench/env/lib/python3.8/site-packages/click/core.py", line 1137, in invoke
    return _process_result(sub_ctx.command.invoke(sub_ctx))
  File "/home/it62070007/frappe-bench/env/lib/python3.8/site-packages/click/core.py", line 1137, in invoke
    return _process_result(sub_ctx.command.invoke(sub_ctx))
  File "/home/it62070007/frappe-bench/env/lib/python3.8/site-packages/click/core.py", line 956, in invoke
    return ctx.invoke(self.callback, **ctx.params)
  File "/home/it62070007/frappe-bench/env/lib/python3.8/site-packages/click/core.py", line 555, in invoke
    return callback(*args, **kwargs)
  File "/home/it62070007/frappe-bench/apps/frappe/frappe/commands/scheduler.py", line 167, in start_worker
    start_worker(queue, quiet = quiet)
  File "/home/it62070007/frappe-bench/apps/frappe/frappe/utils/background_jobs.py", line 151, in start_worker
    Worker(queues, name=get_worker_name(queue)).work(logging_level = logging_level)
  File "/home/it62070007/frappe-bench/env/lib/python3.8/site-packages/rq/worker.py", line 610, in work
    self.register_death()
  File "/home/it62070007/frappe-bench/env/lib/python3.8/site-packages/rq/worker.py", line 318, in register_death
    p.execute()
  File "/home/it62070007/frappe-bench/env/lib/python3.8/site-packages/redis/client.py", line 4019, in execute
    return execute(conn, stack, raise_on_error)
  File "/home/it62070007/frappe-bench/env/lib/python3.8/site-packages/redis/client.py", line 3894, in _execute_transaction
    self.parse_response(connection, '_')
  File "/home/it62070007/frappe-bench/env/lib/python3.8/site-packages/redis/client.py", line 3977, in parse_response
    result = Redis.parse_response(
  File "/home/it62070007/frappe-bench/env/lib/python3.8/site-packages/redis/client.py", line 915, in parse_response
    response = connection.read_response()
  File "/home/it62070007/frappe-bench/env/lib/python3.8/site-packages/redis/connection.py", line 739, in read_response
    response = self._parser.read_response()
  File "/home/it62070007/frappe-bench/env/lib/python3.8/site-packages/redis/connection.py", line 324, in read_response
    raw = self._buffer.readline()
  File "/home/it62070007/frappe-bench/env/lib/python3.8/site-packages/redis/connection.py", line 256, in readline
    self._read_from_socket()
  File "/home/it62070007/frappe-bench/env/lib/python3.8/site-packages/redis/connection.py", line 222, in _read_from_socket
    raise ConnectionError("Error while reading from socket: %s" %
redis.exceptions.ConnectionError: Error while reading from socket: (104, 'Connection reset by peer')
Traceback (most recent call last):
  File "/home/it62070007/frappe-bench/env/lib/python3.8/site-packages/redis/connection.py", line 559, in connect
Traceback (most recent call last):
  File "/home/it62070007/frappe-bench/env/lib/python3.8/site-packages/redis/connection.py", line 559, in connect
    sock = self._connect()
  File "/home/it62070007/frappe-bench/env/lib/python3.8/site-packages/redis/connection.py", line 615, in _connect
    raise err
  File "/home/it62070007/frappe-bench/env/lib/python3.8/site-packages/redis/connection.py", line 603, in _connect
    sock.connect(socket_address)
ConnectionRefusedError: [Errno 111] Connection refused

During handling of the above exception, another exception occurred:

Traceback (most recent call last):
  File "/usr/lib/python3.8/runpy.py", line 194, in _run_module_as_main
    return _run_code(code, main_globals, None,
  File "/usr/lib/python3.8/runpy.py", line 87, in _run_code
    exec(code, run_globals)
  File "/home/it62070007/frappe-bench/apps/frappe/frappe/utils/bench_helper.py", line 99, in <module>
    main()
  File "/home/it62070007/frappe-bench/apps/frappe/frappe/utils/bench_helper.py", line 18, in main
    click.Group(commands=commands)(prog_name='bench')
  File "/home/it62070007/frappe-bench/env/lib/python3.8/site-packages/click/core.py", line 764, in __call__
    return self.main(*args, **kwargs)
  File "/home/it62070007/frappe-bench/env/lib/python3.8/site-packages/click/core.py", line 717, in main
    rv = self.invoke(ctx)
  File "/home/it62070007/frappe-bench/env/lib/python3.8/site-packages/click/core.py", line 1137, in invoke
    return _process_result(sub_ctx.command.invoke(sub_ctx))
  File "/home/it62070007/frappe-bench/env/lib/python3.8/site-packages/click/core.py", line 1137, in invoke
    return _process_result(sub_ctx.command.invoke(sub_ctx))
  File "/home/it62070007/frappe-bench/env/lib/python3.8/site-packages/click/core.py", line 956, in invoke
    return ctx.invoke(self.callback, **ctx.params)
  File "/home/it62070007/frappe-bench/env/lib/python3.8/site-packages/click/core.py", line 555, in invoke
    return callback(*args, **kwargs)
  File "/home/it62070007/frappe-bench/apps/frappe/frappe/commands/scheduler.py", line 167, in start_worker
    start_worker(queue, quiet = quiet)
  File "/home/it62070007/frappe-bench/apps/frappe/frappe/utils/background_jobs.py", line 151, in start_worker
    Worker(queues, name=get_worker_name(queue)).work(logging_level = logging_level)
  File "/home/it62070007/frappe-bench/env/lib/python3.8/site-packages/rq/worker.py", line 610, in work
    self.register_death()
  File "/home/it62070007/frappe-bench/env/lib/python3.8/site-packages/rq/worker.py", line 318, in register_death
    p.execute()
  File "/home/it62070007/frappe-bench/env/lib/python3.8/site-packages/redis/client.py", line 4012, in execute
    conn = self.connection_pool.get_connection('MULTI',
  File "/home/it62070007/frappe-bench/env/lib/python3.8/site-packages/redis/connection.py", line 1192, in get_connection
    connection.connect()
  File "/home/it62070007/frappe-bench/env/lib/python3.8/site-packages/redis/connection.py", line 563, in connect
    raise ConnectionError(self._error_message(e))
redis.exceptions.ConnectionError: Error 111 connecting to localhost:11000. Connection refused.
    sock = self._connect()
  File "/home/it62070007/frappe-bench/env/lib/python3.8/site-packages/redis/connection.py", line 615, in _connect
    raise err
  File "/home/it62070007/frappe-bench/env/lib/python3.8/site-packages/redis/connection.py", line 603, in _connect
    sock.connect(socket_address)
ConnectionRefusedError: [Errno 111] Connection refused

During handling of the above exception, another exception occurred:

Traceback (most recent call last):
  File "/usr/lib/python3.8/runpy.py", line 194, in _run_module_as_main
    return _run_code(code, main_globals, None,
  File "/usr/lib/python3.8/runpy.py", line 87, in _run_code
    exec(code, run_globals)
  File "/home/it62070007/frappe-bench/apps/frappe/frappe/utils/bench_helper.py", line 99, in <module>
    main()
  File "/home/it62070007/frappe-bench/apps/frappe/frappe/utils/bench_helper.py", line 18, in main
    click.Group(commands=commands)(prog_name='bench')
  File "/home/it62070007/frappe-bench/env/lib/python3.8/site-packages/click/core.py", line 764, in __call__
    return self.main(*args, **kwargs)
  File "/home/it62070007/frappe-bench/env/lib/python3.8/site-packages/click/core.py", line 717, in main
    rv = self.invoke(ctx)
  File "/home/it62070007/frappe-bench/env/lib/python3.8/site-packages/click/core.py", line 1137, in invoke
    return _process_result(sub_ctx.command.invoke(sub_ctx))
  File "/home/it62070007/frappe-bench/env/lib/python3.8/site-packages/click/core.py", line 1137, in invoke
    return _process_result(sub_ctx.command.invoke(sub_ctx))
  File "/home/it62070007/frappe-bench/env/lib/python3.8/site-packages/click/core.py", line 956, in invoke
    return ctx.invoke(self.callback, **ctx.params)
  File "/home/it62070007/frappe-bench/env/lib/python3.8/site-packages/click/core.py", line 555, in invoke
    return callback(*args, **kwargs)
  File "/home/it62070007/frappe-bench/apps/frappe/frappe/commands/scheduler.py", line 167, in start_worker
    start_worker(queue, quiet = quiet)
  File "/home/it62070007/frappe-bench/apps/frappe/frappe/utils/background_jobs.py", line 151, in start_worker
    Worker(queues, name=get_worker_name(queue)).work(logging_level = logging_level)
  File "/home/it62070007/frappe-bench/env/lib/python3.8/site-packages/rq/worker.py", line 610, in work
    self.register_death()
  File "/home/it62070007/frappe-bench/env/lib/python3.8/site-packages/rq/worker.py", line 318, in register_death
    p.execute()
  File "/home/it62070007/frappe-bench/env/lib/python3.8/site-packages/redis/client.py", line 4012, in execute
    conn = self.connection_pool.get_connection('MULTI',
  File "/home/it62070007/frappe-bench/env/lib/python3.8/site-packages/redis/connection.py", line 1192, in get_connection
    connection.connect()
  File "/home/it62070007/frappe-bench/env/lib/python3.8/site-packages/redis/connection.py", line 563, in connect
    raise ConnectionError(self._error_message(e))
redis.exceptions.ConnectionError: Error 111 connecting to localhost:11000. Connection refused.
Exception in thread Thread-1:
Traceback (most recent call last):
  File "/usr/lib/python3.8/threading.py", line 932, in _bootstrap_inner
Exception in thread Thread-1:
Traceback (most recent call last):
  File "/usr/lib/python3.8/threading.py", line 932, in _bootstrap_inner
Exception in thread Thread-1:
Traceback (most recent call last):
  File "/usr/lib/python3.8/threading.py", line 932, in _bootstrap_inner
    self.run()
  File "/home/it62070007/frappe-bench/env/lib/python3.8/site-packages/redis/client.py", line 3718, in run
    pubsub.get_message(ignore_subscribe_messages=True,
  File "/home/it62070007/frappe-bench/env/lib/python3.8/site-packages/redis/client.py", line 3617, in get_message
    response = self.parse_response(block=False, timeout=timeout)
  File "/home/it62070007/frappe-bench/env/lib/python3.8/site-packages/redis/client.py", line 3503, in parse_response
    if not block and not conn.can_read(timeout=timeout):
  File "/home/it62070007/frappe-bench/env/lib/python3.8/site-packages/redis/connection.py", line 734, in can_read
    return self._parser.can_read(timeout)
  File "/home/it62070007/frappe-bench/env/lib/python3.8/site-packages/redis/connection.py", line 321, in can_read
    return self._buffer and self._buffer.can_read(timeout)
  File "/home/it62070007/frappe-bench/env/lib/python3.8/site-packages/redis/connection.py", line 230, in can_read
    self._read_from_socket(timeout=timeout,
  File "/home/it62070007/frappe-bench/env/lib/python3.8/site-packages/redis/connection.py", line 201, in _read_from_socket
    raise ConnectionError(SERVER_CLOSED_CONNECTION_ERROR)
redis.exceptions.ConnectionError: Connection closed by server.
    self.run()
  File "/home/it62070007/frappe-bench/env/lib/python3.8/site-packages/redis/client.py", line 3718, in run
    pubsub.get_message(ignore_subscribe_messages=True,
  File "/home/it62070007/frappe-bench/env/lib/python3.8/site-packages/redis/client.py", line 3617, in get_message
    response = self.parse_response(block=False, timeout=timeout)
  File "/home/it62070007/frappe-bench/env/lib/python3.8/site-packages/redis/client.py", line 3503, in parse_response
    if not block and not conn.can_read(timeout=timeout):
  File "/home/it62070007/frappe-bench/env/lib/python3.8/site-packages/redis/connection.py", line 734, in can_read
    return self._parser.can_read(timeout)
  File "/home/it62070007/frappe-bench/env/lib/python3.8/site-packages/redis/connection.py", line 321, in can_read
    return self._buffer and self._buffer.can_read(timeout)
  File "/home/it62070007/frappe-bench/env/lib/python3.8/site-packages/redis/connection.py", line 230, in can_read
    self._read_from_socket(timeout=timeout,
  File "/home/it62070007/frappe-bench/env/lib/python3.8/site-packages/redis/connection.py", line 201, in _read_from_socket
    raise ConnectionError(SERVER_CLOSED_CONNECTION_ERROR)
redis.exceptions.ConnectionError: Connection closed by server.
    self.run()
  File "/home/it62070007/frappe-bench/env/lib/python3.8/site-packages/redis/client.py", line 3718, in run
    pubsub.get_message(ignore_subscribe_messages=True,
  File "/home/it62070007/frappe-bench/env/lib/python3.8/site-packages/redis/client.py", line 3617, in get_message
    response = self.parse_response(block=False, timeout=timeout)
  File "/home/it62070007/frappe-bench/env/lib/python3.8/site-packages/redis/client.py", line 3503, in parse_response
    if not block and not conn.can_read(timeout=timeout):
  File "/home/it62070007/frappe-bench/env/lib/python3.8/site-packages/redis/connection.py", line 734, in can_read
    return self._parser.can_read(timeout)
  File "/home/it62070007/frappe-bench/env/lib/python3.8/site-packages/redis/connection.py", line 321, in can_read
    return self._buffer and self._buffer.can_read(timeout)
  File "/home/it62070007/frappe-bench/env/lib/python3.8/site-packages/redis/connection.py", line 230, in can_read
    self._read_from_socket(timeout=timeout,
  File "/home/it62070007/frappe-bench/env/lib/python3.8/site-packages/redis/connection.py", line 201, in _read_from_socket
    raise ConnectionError(SERVER_CLOSED_CONNECTION_ERROR)
redis.exceptions.ConnectionError: Connection closed by server.
Traceback (most recent call last):
  File "/home/it62070007/frappe-bench/env/lib/python3.8/site-packages/redis/connection.py", line 559, in connect
Traceback (most recent call last):
  File "/home/it62070007/frappe-bench/env/lib/python3.8/site-packages/redis/connection.py", line 559, in connect
Traceback (most recent call last):
  File "/home/it62070007/frappe-bench/env/lib/python3.8/site-packages/redis/connection.py", line 559, in connect
    sock = self._connect()
  File "/home/it62070007/frappe-bench/env/lib/python3.8/site-packages/redis/connection.py", line 615, in _connect
    raise err
  File "/home/it62070007/frappe-bench/env/lib/python3.8/site-packages/redis/connection.py", line 603, in _connect
    sock.connect(socket_address)
ConnectionRefusedError: [Errno 111] Connection refused

During handling of the above exception, another exception occurred:

Traceback (most recent call last):
  File "/usr/lib/python3.8/runpy.py", line 194, in _run_module_as_main
    sock = self._connect()
  File "/home/it62070007/frappe-bench/env/lib/python3.8/site-packages/redis/connection.py", line 615, in _connect
    raise err
  File "/home/it62070007/frappe-bench/env/lib/python3.8/site-packages/redis/connection.py", line 603, in _connect
    sock.connect(socket_address)
ConnectionRefusedError: [Errno 111] Connection refused

During handling of the above exception, another exception occurred:

Traceback (most recent call last):
  File "/usr/lib/python3.8/runpy.py", line 194, in _run_module_as_main
    sock = self._connect()
  File "/home/it62070007/frappe-bench/env/lib/python3.8/site-packages/redis/connection.py", line 615, in _connect
    raise err
  File "/home/it62070007/frappe-bench/env/lib/python3.8/site-packages/redis/connection.py", line 603, in _connect
    sock.connect(socket_address)
ConnectionRefusedError: [Errno 111] Connection refused

During handling of the above exception, another exception occurred:

Traceback (most recent call last):
  File "/usr/lib/python3.8/runpy.py", line 194, in _run_module_as_main
    return _run_code(code, main_globals, None,
  File "/usr/lib/python3.8/runpy.py", line 87, in _run_code
    exec(code, run_globals)
  File "/home/it62070007/frappe-bench/apps/frappe/frappe/utils/bench_helper.py", line 99, in <module>
    return _run_code(code, main_globals, None,
  File "/usr/lib/python3.8/runpy.py", line 87, in _run_code
    exec(code, run_globals)
  File "/home/it62070007/frappe-bench/apps/frappe/frappe/utils/bench_helper.py", line 99, in <module>
    return _run_code(code, main_globals, None,
  File "/usr/lib/python3.8/runpy.py", line 87, in _run_code
    exec(code, run_globals)
  File "/home/it62070007/frappe-bench/apps/frappe/frappe/utils/bench_helper.py", line 99, in <module>
    main()
  File "/home/it62070007/frappe-bench/apps/frappe/frappe/utils/bench_helper.py", line 18, in main
    click.Group(commands=commands)(prog_name='bench')
  File "/home/it62070007/frappe-bench/env/lib/python3.8/site-packages/click/core.py", line 764, in __call__
    main()
  File "/home/it62070007/frappe-bench/apps/frappe/frappe/utils/bench_helper.py", line 18, in main
    click.Group(commands=commands)(prog_name='bench')
  File "/home/it62070007/frappe-bench/env/lib/python3.8/site-packages/click/core.py", line 764, in __call__
    main()
  File "/home/it62070007/frappe-bench/apps/frappe/frappe/utils/bench_helper.py", line 18, in main
    click.Group(commands=commands)(prog_name='bench')
  File "/home/it62070007/frappe-bench/env/lib/python3.8/site-packages/click/core.py", line 764, in __call__
    return self.main(*args, **kwargs)
  File "/home/it62070007/frappe-bench/env/lib/python3.8/site-packages/click/core.py", line 717, in main
    rv = self.invoke(ctx)
  File "/home/it62070007/frappe-bench/env/lib/python3.8/site-packages/click/core.py", line 1137, in invoke
    return _process_result(sub_ctx.command.invoke(sub_ctx))
  File "/home/it62070007/frappe-bench/env/lib/python3.8/site-packages/click/core.py", line 1137, in invoke
    return _process_result(sub_ctx.command.invoke(sub_ctx))
  File "/home/it62070007/frappe-bench/env/lib/python3.8/site-packages/click/core.py", line 956, in invoke
    return ctx.invoke(self.callback, **ctx.params)
  File "/home/it62070007/frappe-bench/env/lib/python3.8/site-packages/click/core.py", line 555, in invoke
    return callback(*args, **kwargs)
  File "/home/it62070007/frappe-bench/apps/frappe/frappe/commands/scheduler.py", line 167, in start_worker
    return self.main(*args, **kwargs)
  File "/home/it62070007/frappe-bench/env/lib/python3.8/site-packages/click/core.py", line 717, in main
    rv = self.invoke(ctx)
  File "/home/it62070007/frappe-bench/env/lib/python3.8/site-packages/click/core.py", line 1137, in invoke
    return _process_result(sub_ctx.command.invoke(sub_ctx))
  File "/home/it62070007/frappe-bench/env/lib/python3.8/site-packages/click/core.py", line 1137, in invoke
    return _process_result(sub_ctx.command.invoke(sub_ctx))
  File "/home/it62070007/frappe-bench/env/lib/python3.8/site-packages/click/core.py", line 956, in invoke
    return ctx.invoke(self.callback, **ctx.params)
  File "/home/it62070007/frappe-bench/env/lib/python3.8/site-packages/click/core.py", line 555, in invoke
    return callback(*args, **kwargs)
  File "/home/it62070007/frappe-bench/apps/frappe/frappe/commands/scheduler.py", line 167, in start_worker
    return self.main(*args, **kwargs)
  File "/home/it62070007/frappe-bench/env/lib/python3.8/site-packages/click/core.py", line 717, in main
    rv = self.invoke(ctx)
  File "/home/it62070007/frappe-bench/env/lib/python3.8/site-packages/click/core.py", line 1137, in invoke
    return _process_result(sub_ctx.command.invoke(sub_ctx))
  File "/home/it62070007/frappe-bench/env/lib/python3.8/site-packages/click/core.py", line 1137, in invoke
    return _process_result(sub_ctx.command.invoke(sub_ctx))
  File "/home/it62070007/frappe-bench/env/lib/python3.8/site-packages/click/core.py", line 956, in invoke
    return ctx.invoke(self.callback, **ctx.params)
  File "/home/it62070007/frappe-bench/env/lib/python3.8/site-packages/click/core.py", line 555, in invoke
    return callback(*args, **kwargs)
  File "/home/it62070007/frappe-bench/apps/frappe/frappe/commands/scheduler.py", line 167, in start_worker
    start_worker(queue, quiet = quiet)
  File "/home/it62070007/frappe-bench/apps/frappe/frappe/utils/background_jobs.py", line 151, in start_worker
    start_worker(queue, quiet = quiet)
  File "/home/it62070007/frappe-bench/apps/frappe/frappe/utils/background_jobs.py", line 151, in start_worker
    start_worker(queue, quiet = quiet)
  File "/home/it62070007/frappe-bench/apps/frappe/frappe/utils/background_jobs.py", line 151, in start_worker
    Worker(queues, name=get_worker_name(queue)).work(logging_level = logging_level)
  File "/home/it62070007/frappe-bench/env/lib/python3.8/site-packages/rq/worker.py", line 611, in work
    Worker(queues, name=get_worker_name(queue)).work(logging_level = logging_level)
  File "/home/it62070007/frappe-bench/env/lib/python3.8/site-packages/rq/worker.py", line 611, in work
    Worker(queues, name=get_worker_name(queue)).work(logging_level = logging_level)
  File "/home/it62070007/frappe-bench/env/lib/python3.8/site-packages/rq/worker.py", line 611, in work
    self.unsubscribe()
  File "/home/it62070007/frappe-bench/env/lib/python3.8/site-packages/rq/worker.py", line 520, in unsubscribe
    self.pubsub.unsubscribe()
  File "/home/it62070007/frappe-bench/env/lib/python3.8/site-packages/redis/client.py", line 3600, in unsubscribe
    self.unsubscribe()
  File "/home/it62070007/frappe-bench/env/lib/python3.8/site-packages/rq/worker.py", line 520, in unsubscribe
    self.pubsub.unsubscribe()
  File "/home/it62070007/frappe-bench/env/lib/python3.8/site-packages/redis/client.py", line 3600, in unsubscribe
    self.unsubscribe()
  File "/home/it62070007/frappe-bench/env/lib/python3.8/site-packages/rq/worker.py", line 520, in unsubscribe
    self.pubsub.unsubscribe()
  File "/home/it62070007/frappe-bench/env/lib/python3.8/site-packages/redis/client.py", line 3600, in unsubscribe
    return self.execute_command('UNSUBSCRIBE', *args)
  File "/home/it62070007/frappe-bench/env/lib/python3.8/site-packages/redis/client.py", line 3466, in execute_command
    self.connection = self.connection_pool.get_connection(
  File "/home/it62070007/frappe-bench/env/lib/python3.8/site-packages/redis/connection.py", line 1192, in get_connection
    connection.connect()
  File "/home/it62070007/frappe-bench/env/lib/python3.8/site-packages/redis/connection.py", line 563, in connect
    raise ConnectionError(self._error_message(e))
redis.exceptions.ConnectionError: Error 111 connecting to localhost:11000. Connection refused.
    return self.execute_command('UNSUBSCRIBE', *args)
  File "/home/it62070007/frappe-bench/env/lib/python3.8/site-packages/redis/client.py", line 3466, in execute_command
    self.connection = self.connection_pool.get_connection(
  File "/home/it62070007/frappe-bench/env/lib/python3.8/site-packages/redis/connection.py", line 1192, in get_connection
    connection.connect()
  File "/home/it62070007/frappe-bench/env/lib/python3.8/site-packages/redis/connection.py", line 563, in connect
    raise ConnectionError(self._error_message(e))
redis.exceptions.ConnectionError: Error 111 connecting to localhost:11000. Connection refused.
    return self.execute_command('UNSUBSCRIBE', *args)
  File "/home/it62070007/frappe-bench/env/lib/python3.8/site-packages/redis/client.py", line 3466, in execute_command
    self.connection = self.connection_pool.get_connection(
  File "/home/it62070007/frappe-bench/env/lib/python3.8/site-packages/redis/connection.py", line 1192, in get_connection
    connection.connect()
  File "/home/it62070007/frappe-bench/env/lib/python3.8/site-packages/redis/connection.py", line 563, in connect
    raise ConnectionError(self._error_message(e))
redis.exceptions.ConnectionError: Error 111 connecting to localhost:11000. Connection refused.
Traceback (most recent call last):
  File "/home/it62070007/frappe-bench/env/lib/python3.8/site-packages/redis/connection.py", line 198, in _read_from_socket
    data = recv(self._sock, socket_read_size)
  File "/home/it62070007/frappe-bench/env/lib/python3.8/site-packages/redis/_compat.py", line 72, in recv
    return sock.recv(*args, **kwargs)
ConnectionResetError: [Errno 104] Connection reset by peer

During handling of the above exception, another exception occurred:

Traceback (most recent call last):
  File "/usr/lib/python3.8/runpy.py", line 194, in _run_module_as_main
    return _run_code(code, main_globals, None,
  File "/usr/lib/python3.8/runpy.py", line 87, in _run_code
    exec(code, run_globals)
  File "/home/it62070007/frappe-bench/apps/frappe/frappe/utils/bench_helper.py", line 99, in <module>
    main()
  File "/home/it62070007/frappe-bench/apps/frappe/frappe/utils/bench_helper.py", line 18, in main
    click.Group(commands=commands)(prog_name='bench')
  File "/home/it62070007/frappe-bench/env/lib/python3.8/site-packages/click/core.py", line 764, in __call__
    return self.main(*args, **kwargs)
  File "/home/it62070007/frappe-bench/env/lib/python3.8/site-packages/click/core.py", line 717, in main
    rv = self.invoke(ctx)
  File "/home/it62070007/frappe-bench/env/lib/python3.8/site-packages/click/core.py", line 1137, in invoke
    return _process_result(sub_ctx.command.invoke(sub_ctx))
  File "/home/it62070007/frappe-bench/env/lib/python3.8/site-packages/click/core.py", line 1137, in invoke
    return _process_result(sub_ctx.command.invoke(sub_ctx))
  File "/home/it62070007/frappe-bench/env/lib/python3.8/site-packages/click/core.py", line 956, in invoke
    return ctx.invoke(self.callback, **ctx.params)
  File "/home/it62070007/frappe-bench/env/lib/python3.8/site-packages/click/core.py", line 555, in invoke
    return callback(*args, **kwargs)
  File "/home/it62070007/frappe-bench/apps/frappe/frappe/commands/scheduler.py", line 167, in start_worker
    start_worker(queue, quiet = quiet)
  File "/home/it62070007/frappe-bench/apps/frappe/frappe/utils/background_jobs.py", line 151, in start_worker
    Worker(queues, name=get_worker_name(queue)).work(logging_level = logging_level)
  File "/home/it62070007/frappe-bench/env/lib/python3.8/site-packages/rq/worker.py", line 610, in work
    self.register_death()
  File "/home/it62070007/frappe-bench/env/lib/python3.8/site-packages/rq/worker.py", line 318, in register_death
    p.execute()
  File "/home/it62070007/frappe-bench/env/lib/python3.8/site-packages/redis/client.py", line 4019, in execute
Exception in thread Thread-1:
Traceback (most recent call last):
  File "/usr/lib/python3.8/threading.py", line 932, in _bootstrap_inner
Exception in thread Exception in thread Thread-1Thread-1:
:
Traceback (most recent call last):
Traceback (most recent call last):
  File "/usr/lib/python3.8/threading.py", line 932, in _bootstrap_inner
  File "/usr/lib/python3.8/threading.py", line 932, in _bootstrap_inner
    return execute(conn, stack, raise_on_error)
  File "/home/it62070007/frappe-bench/env/lib/python3.8/site-packages/redis/client.py", line 3894, in _execute_transaction
    self.parse_response(connection, '_')
  File "/home/it62070007/frappe-bench/env/lib/python3.8/site-packages/redis/client.py", line 3977, in parse_response
    result = Redis.parse_response(
  File "/home/it62070007/frappe-bench/env/lib/python3.8/site-packages/redis/client.py", line 915, in parse_response
    response = connection.read_response()
  File "/home/it62070007/frappe-bench/env/lib/python3.8/site-packages/redis/connection.py", line 739, in read_response
    response = self._parser.read_response()
  File "/home/it62070007/frappe-bench/env/lib/python3.8/site-packages/redis/connection.py", line 324, in read_response
    raw = self._buffer.readline()
  File "/home/it62070007/frappe-bench/env/lib/python3.8/site-packages/redis/connection.py", line 256, in readline
    self._read_from_socket()
  File "/home/it62070007/frappe-bench/env/lib/python3.8/site-packages/redis/connection.py", line 222, in _read_from_socket
    raise ConnectionError("Error while reading from socket: %s" %
redis.exceptions.ConnectionError: Error while reading from socket: (104, 'Connection reset by peer')
    self.run()
  File "/home/it62070007/frappe-bench/env/lib/python3.8/site-packages/redis/client.py", line 3718, in run
    pubsub.get_message(ignore_subscribe_messages=True,
  File "/home/it62070007/frappe-bench/env/lib/python3.8/site-packages/redis/client.py", line 3617, in get_message
    response = self.parse_response(block=False, timeout=timeout)
  File "/home/it62070007/frappe-bench/env/lib/python3.8/site-packages/redis/client.py", line 3503, in parse_response
    if not block and not conn.can_read(timeout=timeout):
  File "/home/it62070007/frappe-bench/env/lib/python3.8/site-packages/redis/connection.py", line 734, in can_read
    return self._parser.can_read(timeout)
  File "/home/it62070007/frappe-bench/env/lib/python3.8/site-packages/redis/connection.py", line 321, in can_read
    return self._buffer and self._buffer.can_read(timeout)
  File "/home/it62070007/frappe-bench/env/lib/python3.8/site-packages/redis/connection.py", line 230, in can_read
    self._read_from_socket(timeout=timeout,
  File "/home/it62070007/frappe-bench/env/lib/python3.8/site-packages/redis/connection.py", line 201, in _read_from_socket
    raise ConnectionError(SERVER_CLOSED_CONNECTION_ERROR)
redis.exceptions.ConnectionError: Connection closed by server.
    self.run()
  File "/home/it62070007/frappe-bench/env/lib/python3.8/site-packages/redis/client.py", line 3718, in run
    pubsub.get_message(ignore_subscribe_messages=True,
  File "/home/it62070007/frappe-bench/env/lib/python3.8/site-packages/redis/client.py", line 3617, in get_message
    response = self.parse_response(block=False, timeout=timeout)
  File "/home/it62070007/frappe-bench/env/lib/python3.8/site-packages/redis/client.py", line 3503, in parse_response
    if not block and not conn.can_read(timeout=timeout):
  File "/home/it62070007/frappe-bench/env/lib/python3.8/site-packages/redis/connection.py", line 734, in can_read
    return self._parser.can_read(timeout)
  File "/home/it62070007/frappe-bench/env/lib/python3.8/site-packages/redis/connection.py", line 321, in can_read
    return self._buffer and self._buffer.can_read(timeout)
  File "/home/it62070007/frappe-bench/env/lib/python3.8/site-packages/redis/connection.py", line 230, in can_read
    self._read_from_socket(timeout=timeout,
  File "/home/it62070007/frappe-bench/env/lib/python3.8/site-packages/redis/connection.py", line 201, in _read_from_socket
    raise ConnectionError(SERVER_CLOSED_CONNECTION_ERROR)
redis.exceptionsTraceback (most recent call last):
  File "/home/it62070007/frappe-bench/env/lib/python3.8/site-packages/redis/connection.py", line 559, in connect
.    sock = self._connect()
  File "/home/it62070007/frappe-bench/env/lib/python3.8/site-packages/redis/connection.py", line 615, in _connect
    raise err
  File "/home/it62070007/frappe-bench/env/lib/python3.8/site-packages/redis/connection.py", line 603, in _connect
    sock.connect(socket_address)
ConnectionRefusedError: [Errno 111] Connection refused

During handling of the above exception, another exception occurred:

Traceback (most recent call last):
ConnectionError  File "/usr/lib/python3.8/runpy.py", line 194, in _run_module_as_main
Traceback (most recent call last):
  File "/home/it62070007/frappe-bench/env/lib/python3.8/site-packages/redis/connection.py", line 559, in connect
    sock = self._connect()
  File "/home/it62070007/frappe-bench/env/lib/python3.8/site-packages/redis/connection.py", line 615, in _connect
    raise err
  File "/home/it62070007/frappe-bench/env/lib/python3.8/site-packages/redis/connection.py", line 603, in _connect
    sock.connect(socket_address)
ConnectionRefusedError: [Errno 111] Connection refused

During handling of the above exception, another exception occurred:

Traceback (most recent call last):
    return _run_code(code, main_globals, None,
  File "/usr/lib/python3.8/runpy.py", line 87, in _run_code
    exec(code, run_globals)
  File "/home/it62070007/frappe-bench/apps/frappe/frappe/utils/bench_helper.py", line 99, in <module>
    main()
  File "/home/it62070007/frappe-bench/apps/frappe/frappe/utils/bench_helper.py", line 18, in main
    click.Group(commands=commands)(prog_name='bench')
  File "/home/it62070007/frappe-bench/env/lib/python3.8/site-packages/click/core.py", line 764, in __call__
    return self.main(*args, **kwargs)
  File "/home/it62070007/frappe-bench/env/lib/python3.8/site-packages/click/core.py", line 717, in main
    rv = self.invoke(ctx)
  File "/home/it62070007/frappe-bench/env/lib/python3.8/site-packages/click/core.py", line 1137, in invoke
:   File "/usr/lib/python3.8/runpy.py", line 194, in _run_module_as_main
    return _run_code(code, main_globals, None,
  File "/usr/lib/python3.8/runpy.py", line 87, in _run_code
    exec(code, run_globals)
  File "/home/it62070007/frappe-bench/apps/frappe/frappe/utils/bench_helper.py", line 99, in <module>
    main()
  File "/home/it62070007/frappe-bench/apps/frappe/frappe/utils/bench_helper.py", line 18, in main
    click.Group(commands=commands)(prog_name='bench')
  File "/home/it62070007/frappe-bench/env/lib/python3.8/site-packages/click/core.py", line 764, in __call__
    return self.main(*args, **kwargs)
  File "/home/it62070007/frappe-bench/env/lib/python3.8/site-packages/click/core.py", line 717, in main
    return _process_result(sub_ctx.command.invoke(sub_ctx))
  File "/home/it62070007/frappe-bench/env/lib/python3.8/site-packages/click/core.py", line 1137, in invoke
    return _process_result(sub_ctx.command.invoke(sub_ctx))
  File "/home/it62070007/frappe-bench/env/lib/python3.8/site-packages/click/core.py", line 956, in invoke
    return ctx.invoke(self.callback, **ctx.params)
  File "/home/it62070007/frappe-bench/env/lib/python3.8/site-packages/click/core.py", line 555, in invoke
    return callback(*args, **kwargs)
  File "/home/it62070007/frappe-bench/apps/frappe/frappe/commands/scheduler.py", line 167, in start_worker
    start_worker(queue, quiet = quiet)
  File "/home/it62070007/frappe-bench/apps/frappe/frappe/utils/background_jobs.py", line 151, in start_worker
    Worker(queues, name=get_worker_name(queue)).work(logging_level = logging_level)
  File "/home/it62070007/frappe-bench/env/lib/python3.8/site-packages/rq/worker.py", line 610, in work
    self.register_death()
  File "/home/it62070007/frappe-bench/env/lib/python3.8/site-packages/rq/worker.py", line 318, in register_death
    p.execute()
  File "/home/it62070007/frappe-bench/env/lib/python3.8/site-packages/redis/client.py", line 4012, in execute
    conn = self.connection_pool.get_connection('MULTI',
  File "/home/it62070007/frappe-bench/env/lib/python3.8/site-packages/redis/connection.py", line 1192, in get_connection
    connection.connect()
  File "/home/it62070007/frappe-bench/env/lib/python3.8/site-packages/redis/connection.py", line 563, in connect
    raise ConnectionError(self._error_message(e))
redis.exceptions.ConnectionError: Error 111 connecting to localhost:11000. Connection refused.
    rv = self.invoke(ctx)
  File "/home/it62070007/frappe-bench/env/lib/python3.8/site-packages/click/core.py", line 1137, in invoke
Connection closed by server.    return _process_result(sub_ctx.command.invoke(sub_ctx))
  File "/home/it62070007/frappe-bench/env/lib/python3.8/site-packages/click/core.py", line 1137, in invoke
    return _process_result(sub_ctx.command.invoke(sub_ctx))
  File "/home/it62070007/frappe-bench/env/lib/python3.8/site-packages/click/core.py", line 956, in invoke
    return ctx.invoke(self.callback, **ctx.params)
  File "/home/it62070007/frappe-bench/env/lib/python3.8/site-packages/click/core.py", line 555, in invoke
    return callback(*args, **kwargs)
  File "/home/it62070007/frappe-bench/apps/frappe/frappe/commands/scheduler.py", line 167, in start_worker
    start_worker(queue, quiet = quiet)
  File "/home/it62070007/frappe-bench/apps/frappe/frappe/utils/background_jobs.py", line 151, in start_worker
    Worker(queues, name=get_worker_name(queue)).work(logging_level = logging_level)
  File "/home/it62070007/frappe-bench/env/lib/python3.8/site-packages/rq/worker.py", line 610, in work
    self.register_death()
  File "/home/it62070007/frappe-bench/env/lib/python3.8/site-packages/rq/worker.py", line 318, in register_death
    p.execute()
  File "/home/it62070007/frappe-bench/env/lib/python3.8/site-packages/redis/client.py", line 4012, in execute
    conn = self.connection_pool.get_connection('MULTI',
  File "/home/it62070007/frappe-bench/env/lib/python3.8/site-packages/redis/connection.py", line 1192, in get_connection
    connection.connect()
  File "/home/it62070007/frappe-bench/env/lib/python3.8/site-packages/redis/connection.py", line 563, in connect
    raise ConnectionError(self._error_message(e))
redis.exceptions.ConnectionError: Error 111 connecting to localhost:11000. Connection refused.

    self.run()
  File "/home/it62070007/frappe-bench/env/lib/python3.8/site-packages/redis/client.py", line 3718, in run
    pubsub.get_message(ignore_subscribe_messages=True,
  File "/home/it62070007/frappe-bench/env/lib/python3.8/site-packages/redis/client.py", line 3617, in get_message
    response = self.parse_response(block=False, timeout=timeout)
  File "/home/it62070007/frappe-bench/env/lib/python3.8/site-packages/redis/client.py", line 3503, in parse_response
    if not block and not conn.can_read(timeout=timeout):
  File "/home/it62070007/frappe-bench/env/lib/python3.8/site-packages/redis/connection.py", line 734, in can_read
    return self._parser.can_read(timeout)
  File "/home/it62070007/frappe-bench/env/lib/python3.8/site-packages/redis/connection.py", line 321, in can_read
    return self._buffer and self._buffer.can_read(timeout)
  File "/home/it62070007/frappe-bench/env/lib/python3.8/site-packages/redis/connection.py", line 230, in can_read
    self._read_from_socket(timeout=timeout,
  File "/home/it62070007/frappe-bench/env/lib/python3.8/site-packages/redis/connection.py", line 201, in _read_from_socket
    raise ConnectionError(SERVER_CLOSED_CONNECTION_ERROR)
redis.exceptions.ConnectionError: Connection closed by server.
Exception in thread Thread-1:
Traceback (most recent call last):
  File "/usr/lib/python3.8/threading.py", line 932, in _bootstrap_inner
Exception in thread Thread-1:
Traceback (most recent call last):
  File "/usr/lib/python3.8/threading.py", line 932, in _bootstrap_inner
Exception in thread Thread-1:
Traceback (most recent call last):
  File "/usr/lib/python3.8/threading.py", line 932, in _bootstrap_inner
    self.run()
  File "/home/it62070007/frappe-bench/env/lib/python3.8/site-packages/redis/client.py", line 3718, in run
    self.run()
  File "/home/it62070007/frappe-bench/env/lib/python3.8/site-packages/redis/client.py", line 3718, in run
    self.run()
  File "/home/it62070007/frappe-bench/env/lib/python3.8/site-packages/redis/client.py", line 3718, in run
    pubsub.get_message(ignore_subscribe_messages=True,
  File "/home/it62070007/frappe-bench/env/lib/python3.8/site-packages/redis/client.py", line 3617, in get_message
    response = self.parse_response(block=False, timeout=timeout)
  File "/home/it62070007/frappe-bench/env/lib/python3.8/site-packages/redis/client.py", line 3503, in parse_response
    if not block and not conn.can_read(timeout=timeout):
  File "/home/it62070007/frappe-bench/env/lib/python3.8/site-packages/redis/connection.py", line 734, in can_read
    pubsub.get_message(ignore_subscribe_messages=True,
  File "/home/it62070007/frappe-bench/env/lib/python3.8/site-packages/redis/client.py", line 3617, in get_message
    response = self.parse_response(block=False, timeout=timeout)
  File "/home/it62070007/frappe-bench/env/lib/python3.8/site-packages/redis/client.py", line 3503, in parse_response
    if not block and not conn.can_read(timeout=timeout):
  File "/home/it62070007/frappe-bench/env/lib/python3.8/site-packages/redis/connection.py", line 734, in can_read
    pubsub.get_message(ignore_subscribe_messages=True,
  File "/home/it62070007/frappe-bench/env/lib/python3.8/site-packages/redis/client.py", line 3617, in get_message
    response = self.parse_response(block=False, timeout=timeout)
  File "/home/it62070007/frappe-bench/env/lib/python3.8/site-packages/redis/client.py", line 3503, in parse_response
    if not block and not conn.can_read(timeout=timeout):
  File "/home/it62070007/frappe-bench/env/lib/python3.8/site-packages/redis/connection.py", line 734, in can_read
    return self._parser.can_read(timeout)
  File "/home/it62070007/frappe-bench/env/lib/python3.8/site-packages/redis/connection.py", line 321, in can_read
    return self._buffer and self._buffer.can_read(timeout)
  File "/home/it62070007/frappe-bench/env/lib/python3.8/site-packages/redis/connection.py", line 230, in can_read
    self._read_from_socket(timeout=timeout,
  File "/home/it62070007/frappe-bench/env/lib/python3.8/site-packages/redis/connection.py", line 201, in _read_from_socket
    raise ConnectionError(SERVER_CLOSED_CONNECTION_ERROR)
redis.exceptions.ConnectionError: Connection closed by server.
    return self._parser.can_read(timeout)
  File "/home/it62070007/frappe-bench/env/lib/python3.8/site-packages/redis/connection.py", line 321, in can_read
    return self._buffer and self._buffer.can_read(timeout)
  File "/home/it62070007/frappe-bench/env/lib/python3.8/site-packages/redis/connection.py", line 230, in can_read
    self._read_from_socket(timeout=timeout,
  File "/home/it62070007/frappe-bench/env/lib/python3.8/site-packages/redis/connection.py", line 201, in _read_from_socket
    raise ConnectionError(SERVER_CLOSED_CONNECTION_ERROR)
redis.exceptions.ConnectionError: Connection closed by server.
    return self._parser.can_read(timeout)
  File "/home/it62070007/frappe-bench/env/lib/python3.8/site-packages/redis/connection.py", line 321, in can_read
    return self._buffer and self._buffer.can_read(timeout)
  File "/home/it62070007/frappe-bench/env/lib/python3.8/site-packages/redis/connection.py", line 230, in can_read
    self._read_from_socket(timeout=timeout,
  File "/home/it62070007/frappe-bench/env/lib/python3.8/site-packages/redis/connection.py", line 201, in _read_from_socket
    raise ConnectionError(SERVER_CLOSED_CONNECTION_ERROR)
redis.exceptions.ConnectionError: Connection closed by server.
